Workbook

Sheet Summary
A1: Carolina Panthers — Valuation Summary ('Football Field')
A2: All figures $mm, enterprise value. Prepared by Vincent Huang, UNC Charlotte, Oct 2026. Links pull from the other tabs; change Inputs and this page updates.
A4: Method | B4: Low | C4: High | D4: Midpoint | E4: Width (chart) | F4: Basis
A5: Published valuations (Sportico / Forbes) | B5: =Inputs!$B$7 -> 8070 | C5: =Inputs!$B$6 -> 8100 | D5: =(B5+C5)/2 -> 8085 | E5: =C5-B5 -> 30 | F5: Sept 2026 lists
A6: Precedent transactions (deal min – median) | B6: =Comps!$C$25 -> 5710.8365 | C6: =Comps!$C$26 -> 8209.7561 | D6: =(B6+C6)/2 -> 6960.2963 | E6: =C6-B6 -> 2498.9196 | F6: EV/revenue from 2022–26 NFL sales × 2025 revenue
A7: Precedent transactions (median – max) | B7: =Comps!$C$26 -> 8209.7561 | C7: =Comps!$C$29 -> 11188.889 | D7: =(B7+C7)/2 -> 9699.3225 | E7: =C7-B7 -> 2979.1328 | F7: Same, upper half of the range
A8: DCF — exit multiple (7–10% discount, 10–14x) | B8: =MIN(DCF!B49:F52) -> 4953.8218 | C8: =MAX(DCF!B49:F52) -> 8813.8442 | D8: =(B8+C8)/2 -> 6883.833 | E8: =C8-B8 -> 3860.0224 | F8: Cash flows + terminal multiple
A9: DCF — perpetuity growth | B9: =MIN(DCF!B56:F59) -> 1256.0066 | C9: =MAX(DCF!B56:F59) -> 4144.3877 | D9: =(B9+C9)/2 -> 2700.1971 | E9: =C9-B9 -> 2888.3811 | F9: Cash flows only; shows the scarcity premium
A10: PE entry (after 20% LP discount) | B10: ='PE Stake'!C7*(1-'PE Stake'!C8) -> 6350.4 | C10: ='PE Stake'!C7 -> 7938 | D10: =(B10+C10)/2 -> 7144.2 | E10: =C10-B10 -> 1587.6 | F10: What a minority investor actually pays vs headline
A13: Headline conclusions
A14: Fair enterprise value range — my view ($mm) | B14: 7100 | C14: 8300
A15: Recommendation for a 10% PE stake at $8.1bn headline | B15: PASS at $8.1bn headline / 20% LP discount (12.5% base IRR < 15% hurdle). BUY at a 30%+ LP discount (effective entry ≤ $5.6bn), or if the 2029 media opt-out is expected to lift national revenue 15%+.
A16: Base-case PE IRR (from PE Stake tab) | B16: ='PE Stake'!C20 -> 0.12483583
A17: Market value ÷ cash-flow (DCF Gordon) value | B17: =DCF!B43 -> 3.7444685
A18: Value CAGR since 2017 (Forbes) | B18: =Historicals!B18 -> 0.17042785

Sheet Inputs
A1: Carolina Panthers Valuation — Key Inputs & Assumptions
A2: Blue = hardcoded input (edit these). Yellow = the assumptions that move the answer most. Every number has a source or a stated reason.
A4: Assumption | B4: Value | C4: Source / rationale
A5: MARKET DATA (2025 season, Forbes Sept 2026)
A6: Panthers enterprise value — Forbes | B6: 8100 | C6: Forbes NFL Team Valuations, Sept 9 2026 (#26 of 32). forbes.com/teams/carolina-panthers
A7: Panthers enterprise value — Sportico | B7: 8070 | C7: Sportico 2026 NFL valuations, via Charlotte Business Journal / Yahoo Sports
A8: Revenue, 2025 season ($mm) | B8: 646 | C8: Forbes; net of stadium debt service, excludes playoffs
A9: Operating income / EBITDA, 2025 season ($mm) | B9: 88 | C9: Forbes
A10: Player expenses ($mm) | B10: 366 | C10: Forbes; includes benefits and bonuses
A11: Debt as % of value | B11: 0.02 | C11: Forbes (includes stadium debt)
A12: Tepper purchase price, 2018 ($mm) | B12: 2280 | C12: Forbes; CBJ cites $3.0bn inflation-adjusted
A13: League average team value ($mm) | B13: 9500 | C13: Forbes 2026 average, +34% y/y
A14: League average EV / trailing revenue | B14: 13.4 | C14: Forbes 2026
A15: REVENUE SPLIT (assumption)
A16: National (shared) revenue per team, 2025 ($mm) | B16: 455 | C16: Sportico: national revenue 'more than $450mm' per team in 2025 (gross). ASSUMPTION — refine with Packers annual report
A17: Local revenue, 2025 ($mm) | B17: =B8-B16 -> 191 | C17: Derived: total revenue less national
A18: Other operating expenses, 2025 ($mm) | B18: =B8-B10-B9 -> 192 | C18: Derived: revenue − player costs − EBITDA
A19: GROWTH ASSUMPTIONS
A20: National revenue growth, 2026–2029 | B20: 0.06 | C20: Current media deal ($125bn / 11 yrs to 2033) steps up ~5–7%/yr; Sportico projects >$800mm per team by 2035
A21: Media renegotiation uplift in 2030 (one-time) | B21: 0.1 | C21: NFL can opt out of media deals after 2029 season; ASSUMPTION of a 10% step-up. Set to 0% for a conservative case
A22: National revenue growth, 2030–2035 | B22: 0.05 | C22: Assumption
A23: Local revenue growth (base) | B23: 0.03 | C23: Assumption: ~inflation + modest ticket/sponsorship pricing
A24: Stadium renovation uplift to local revenue (one-time) | B24: 0.2 | C24: ASSUMPTION. $800mm phase-1 renovation of Bank of America Stadium (city $650mm + TSE $150mm); premium seating / sponsorship typically lifts local revenue 15–30% post-renovation
A25: Year renovation uplift hits | B25: 2028 | C25: Phase 1 funded over 4 years from 2024 approval; assumption
A26: Player cost growth (tracks salary cap) | B26: =B20 -> 0.06 | C26: Cap is set as a share of league revenue, so player costs grow with national revenue
A27: Other opex growth | B27: 0.03 | C27: Assumption
A28: CASH FLOW & DISCOUNTING
A29: Tax rate on operating income | B29: 0.25 | C29: ASSUMPTION. Team is a pass-through; owner-level taxes approximated at 25%
A30: Maintenance capex per year ($mm) | B30: 10 | C30: Assumption
A31: TSE stadium contribution 2026–2029 ($mm/yr) | B31: 37.5 | C31: $150mm over four years (WFAE, June 2024)
A32: TSE stadium contribution 2030–2035 ($mm/yr) | B32: 38 | C32: ~$420mm committed 2029–2039 (WFAE) ≈ $38mm/yr
A33: Discount rate (cost of equity) | B33: 0.08 | C33: ASSUMPTION. Low-beta scarcity asset; NFL teams have never traded at a loss. Range 7–10%
A34: Terminal exit multiple (EV / revenue) | B34: 12 | C34: Below the 13.4x league average to be conservative; Broncos traded at 8.8x in 2022
A35: Terminal growth rate (Gordon) | B35: 0.04 | C35: Assumption; long-run league revenue growth
A36: PRIVATE EQUITY STAKE CASE
A37: Stake purchased | B37: 0.1 | C37: NFL maximum PE stake per team is 10% (min 3%); 6-year minimum hold
A38: Minority / LP discount to headline value | B38: 0.2 | C38: ASSUMPTION. Reported LP discounts of 15–30%; Sportico notes PE bids below headline (49ers bid ~$7.1bn vs $8.6bn value)
A39: Hold period (years) | B39: 6 | C39: NFL rule: minimum six-year hold
A40: Annual appreciation of team value — Base | B40: 0.1 | C40: Panthers: +17% annualized 2017–2026; league avg +34% last year. Base case assumes slowdown
A41: Annual appreciation — Bear | B41: 0.05 | C41: Assumption
...

Sheet Historicals
A1: Panthers Financial History (Forbes, 2017–2025 seasons)
A2: Source: forbes.com/teams/carolina-panthers. Forbes labels each season by publication year; here 'Season' = the year the games were played. All $mm.
A4: Season | B4: 2017 | C4: 2018 | D4: 2019 | E4: 2020 | F4: 2021 | G4: 2022 | H4: 2023 | I4: 2024 | J4: 2025
A5: Team value (Forbes, Sept following season) | B5: 2300 | C5: 2400 | D5: 2600 | E5: 2900 | F5: 3600 | G5: 4100 | H5: 4500 | I5: 5700 | J5: 8100
A6: Revenue | B6: 396 | C6: 424 | D6: 447 | E6: 351 | F6: 501 | G6: 530 | H6: 574 | I6: 588 | J6: 646
A7: Operating income (EBITDA) | B7: 62 | C7: 78 | D7: 96 | E7: -22 | F7: 139 | G7: 72 | H7: 109 | I7: 36 | J7: 88
A8: Player expenses | B8: 218 | C8: 223 | D8: 224 | E8: 241 | F8: 224 | G8: 282 | H8: 284 | I8: 369 | J8: 366
A10: Derived metrics
A11: Revenue growth y/y | C11: =IF(B6=0,0,C6/B6-1) -> 0.070707071 | D11: =IF(C6=0,0,D6/C6-1) -> 0.054245283 | E11: =IF(D6=0,0,E6/D6-1) -> -0.2147651 | F11: =IF(E6=0,0,F6/E6-1) -> 0.42735043 | G11: =IF(F6=0,0,G6/F6-1) -> 0.057884232 | H11: =IF(G6=0,0,H6/G6-1) -> 0.083018868 | I11: =IF(H6=0,0,I6/H6-1) -> 0.024390244 | J11: =IF(I6=0,0,J6/I6-1) -> 0.098639456
A12: EBITDA margin | B12: =B7/B6 -> 0.15656566 | C12: =C7/C6 -> 0.18396226 | D12: =D7/D6 -> 0.2147651 | E12: =E7/E6 -> -0.062678063 | F12: =F7/F6 -> 0.27744511 | G12: =G7/G6 -> 0.13584906 | H12: =H7/H6 -> 0.18989547 | I12: =I7/I6 -> 0.06122449 | J12: =J7/J6 -> 0.13622291
A13: Player costs % of revenue | B13: =B8/B6 -> 0.55050505 | C13: =C8/C6 -> 0.5259434 | D13: =D8/D6 -> 0.50111857 | E13: =E8/E6 -> 0.68660969 | F13: =F8/F6 -> 0.44710579 | G13: =G8/G6 -> 0.53207547 | H13: =H8/H6 -> 0.49477352 | I13: =I8/I6 -> 0.62755102 | J13: =J8/J6 -> 0.56656347
A14: EV / revenue | B14: =B5/B6 -> 5.8080808 | C14: =C5/C6 -> 5.6603774 | D14: =D5/D6 -> 5.8165548 | E14: =E5/E6 -> 8.2621083 | F14: =F5/F6 -> 7.1856287 | G14: =G5/G6 -> 7.7358491 | H14: =H5/H6 -> 7.8397213 | I14: =I5/I6 -> 9.6938776 | J14: =J5/J6 -> 12.5387
A15: EV / EBITDA | B15: =IF(B7<=0,"n.m.",B5/B7) -> 37.096774 | C15: =IF(C7<=0,"n.m.",C5/C7) -> 30.769231 | D15: =IF(D7<=0,"n.m.",D5/D7) -> 27.083333 | E15: =IF(E7<=0,"n.m.",E5/E7) -> n.m. | F15: =IF(F7<=0,"n.m.",F5/F7) -> 25.899281 | G15: =IF(G7<=0,"n.m.",G5/G7) -> 56.944444 | H15: =IF(H7<=0,"n.m.",H5/H7) -> 41.284404 | I15: =IF(I7<=0,"n.m.",I5/I7) -> 158.33333 | J15: =IF(J7<=0,"n.m.",J5/J7) -> 92.045455
A16: Value growth y/y | C16: =C5/B5-1 -> 0.043478261 | D16: =D5/C5-1 -> 0.083333333 | E16: =E5/D5-1 -> 0.11538462 | F16: =F5/E5-1 -> 0.24137931 | G16: =G5/F5-1 -> 0.13888889 | H16: =H5/G5-1 -> 0.097560976 | I16: =I5/H5-1 -> 0.26666667 | J16: =J5/I5-1 -> 0.42105263
A18: Value CAGR 2017–2025 | B18: =(J5/B5)^(1/8)-1 -> 0.17042785
A19: Revenue CAGR 2017–2025 | B19: =(J6/B6)^(1/8)-1 -> 0.063082983
A20: Value multiple since Tepper's 2018 purchase ($2.28bn) | B20: =J5/Inputs!$B$12 -> 3.5526316
A22: Takeaway: value has compounded ~17%/yr while revenue grew ~6%/yr — the multiple expanded from ~5.8x to ~12.5x revenue. Most of the return came from scarcity and league-wide repricing, not Panthers cash flow.

Sheet Comps
A1: Precedent Transactions — NFL Control and Minority Stake Sales (2022–2026)
A2: Implied enterprise values as reported. Minority deals often include limited-partner discounts and non-team assets; read the notes.
A4: Team | B4: Date | C4: Buyer | D4: Stake | E4: Implied value ($mm) | F4: Trailing revenue ($mm) | G4: EV / revenue | H4: Type | I4: Notes / source
A5: Seattle Seahawks | B5: 2026 | C5: Khosla family group | D5: 1 | E5: 9600 | F5: 659 | G5: =E5/F5 -> 14.567527 | H5: Control | I5: Record control purchase (Forbes: 14.6x). Trailing = 2025-season revenue, Forbes Seahawks page
A6: Denver Broncos | B6: 2022 | C6: Walton-Penner | D6: 1 | E6: 4650 | F6: 526 | G6: =E6/F6 -> 8.8403042 | H6: Control | I6: Pre-PE era benchmark. Trailing = 2021-season revenue, Forbes Broncos page (Forbes cites 8.8x)
A7: Washington Commanders | B7: 2023 | C7: Josh Harris group | D7: 1 | E7: 6050 | F7: 545 | G7: =E7/F7 -> 11.100917 | H7: Control | I7: Trailing = 2022-season revenue, Forbes Commanders page
A8: New York Giants | B8: Oct 2025 | C8: Julia Koch | D8: 0.1 | E8: 10300 | F8: 707 | G8: =E8/F8 -> 14.5686 | H8: Minority | I8: CNBC: NFL approved minority stake at $10.3bn. Trailing = 2024-season revenue, Forbes Giants page
A9: Atlanta Falcons | B9: Aug 2025 | C9: Arctos (PE) | D9: 0.1 | E9: 10600 | F9: 612 | G9: =E9/F9 -> 17.320261 | H9: PE minority | I9: CNBC/Forbes: blended $10.6bn. Trailing = 2024-season revenue (Forbes Falcons page). Outlier: 2025 revenue jumped to $805mm, so buyers priced forward revenue
A10: Cleveland Browns | B10: May 2025 | C10: Arctos (PE) | D10: 0.03 | E10: 9000 | F10: 685 | G10: =E10/F10 -> 13.138686 | H10: PE minority | I10: Sportico via Forbes: ~3% at $9bn. Trailing = 2024-season revenue, Forbes Browns page
A11: Las Vegas Raiders | B11: Spring 2025 | C11: Egon Durban group | D11: 0.25 | E11: 9900 | F11: 779 | G11: =E11/F11 -> 12.708601 | H11: Minority | I11: Forbes: 25% at $9.9bn (separate 3.5% piece at $11bn). Trailing = 2024-season revenue, Forbes Raiders page
A12: Miami Dolphins | B12: Mar 2025 | C12: Ares (PE) | D12: 0.1 | E12: 8100 | F12: 656 | G12: =E12/F12 -> 12.347561 | H12: PE minority | I12: Sportico: Ares 10% at $8.1bn. Trailing = 2024-season revenue, Forbes Dolphins page. Later $12.5bn holdco deal includes stadium + F1 race, excluded
A13: Buffalo Bills | B13: 2024 | C13: Arctos (PE) | D13: 0.1 | E13: 5800 | F13: 552 | G13: =E13/F13 -> 10.507246 | H13: PE minority | I13: Sportico: Arctos entered at $5.8bn. Trailing = 2023-season revenue, Forbes Bills page
A15: Summary statistics (EV / revenue)
A16: Control deals — mean | G16: =AVERAGEIF(H5:H13,"Control",G5:G13) -> 11.502916
A17: Minority & PE deals — mean | G17: =AVERAGEIF(H5:H13,"*inority",G5:G13) -> 13.431826
A18: All deals — median | G18: =MEDIAN(G5:G13) -> 12.708601
A19: All deals — low | G19: =MIN(G5:G13) -> 8.8403042
A20: All deals — high | G20: =MAX(G5:G13) -> 17.320261
A21: Forbes league average (2026) | G21: =Inputs!$B$14 -> 13.4
A23: Implied Panthers enterprise value ($mm) = multiple × 2025 revenue
A24: Case | B24: Multiple | C24: Implied EV | D24: Less debt | E24: Equity value | F24: vs Forbes $8.1bn
A25: Low (deal minimum) | B25: =G19 -> 8.8403042 | C25: =B25*Inputs!$B$8 -> 5710.8365 | D25: =-Inputs!$B$11*C25 -> -114.21673 | E25: =C25+D25 -> 5596.6198 | F25: =C25/Inputs!$B$6-1 -> -0.29495846
A26: Median | B26: =G18 -> 12.708601 | C26: =B26*Inputs!$B$8 -> 8209.7561 | D26: =-Inputs!$B$11*C26 -> -164.19512 | E26: =C26+D26 -> 8045.561 | F26: =C26/Inputs!$B$6-1 -> 0.013550136
A27: Minority/PE mean | B27: =G17 -> 13.431826 | C27: =B27*Inputs!$B$8 -> 8676.9595 | D27: =-Inputs!$B$11*C27 -> -173.53919 | E27: =C27+D27 -> 8503.4203 | F27: =C27/Inputs!$B$6-1 -> 0.071229572
A28: Control mean | B28: =G16 -> 11.502916 | C28: =B28*Inputs!$B$8 -> 7430.8838 | D28: =-Inputs!$B$11*C28 -> -148.61768 | E28: =C28+D28 -> 7282.2661 | F28: =C28/Inputs!$B$6-1 -> -0.082606942
A29: High (deal maximum) | B29: =G20 -> 17.320261 | C29: =B29*Inputs!$B$8 -> 11188.889 | D29: =-Inputs!$B$11*C29 -> -223.77778 | E29: =C29+D29 -> 10965.111 | F29: =C29/Inputs!$B$6-1 -> 0.38134431
A30: League average | B30: =G21 -> 13.4 | C30: =B30*Inputs!$B$8 -> 8656.4 | D30: =-Inputs!$B$11*C30 -> -173.128 | E30: =C30+D30 -> 8483.272 | F30: =C30/Inputs!$B$6-1 -> 0.068691358
A32: Why the Panthers should trade below the league average: mid-sized market (2.9mm metro), seven straight non-playoff seasons 2018–2024 before a 2025 wild-card return, below-average operating income ($88mm vs league leaders $300mm+), and a stadium that is 30 years old until the renovation lands. Why not far below: every NFL team is a 1-of-32 scarcity asset with guaranteed national revenue, and new-stadium economics arrive in 2028.

Sheet DCF
A1: Discounted Cash Flow — Owner Cash Flows, 2026–2035 ($mm)
A2: What the team is worth on cash flow alone. The gap to market value is the scarcity premium — the core of the pitch.
A4: Season | B4: 2025A | C4: 2026 | D4: 2027 | E4: 2028 | F4: 2029 | G4: 2030 | H4: 2031 | I4: 2032 | J4: 2033 | K4: 2034 | L4: 2035
B5: 2025 | C5: 2026 | D5: 2027 | E5: 2028 | F5: 2029 | G5: 2030 | H5: 2031 | I5: 2032 | J5: 2033 | K5: 2034 | L5: 2035
A7: National revenue | B7: =Inputs!$B$16 -> 455 | C7: =B7*(1+IF(C$5<=2029,Inputs!$B$20,Inputs!$B$22))*(1+IF(C$5=2030,Inputs!$B$21,0)) -> 482.3 | D7: =C7*(1+IF(D$5<=2029,Inputs!$B$20,Inputs!$B$22))*(1+IF(D$5=2030,Inputs!$B$21,0)) -> 511.238 | E7: =D7*(1+IF(E$5<=2029,Inputs!$B$20,Inputs!$B$22))*(1+IF(E$5=2030,Inputs!$B$21,0)) -> 541.91228 | F7: =E7*(1+IF(F$5<=2029,Inputs!$B$20,Inputs!$B$22))*(1+IF(F$5=2030,Inputs!$B$21,0)) -> 574.42702 | G7: =F7*(1+IF(G$5<=2029,Inputs!$B$20,Inputs!$B$22))*(1+IF(G$5=2030,Inputs!$B$21,0)) -> 663.4632 | H7: =G7*(1+IF(H$5<=2029,Inputs!$B$20,Inputs!$B$22))*(1+IF(H$5=2030,Inputs!$B$21,0)) -> 696.63636 | I7: =H7*(1+IF(I$5<=2029,Inputs!$B$20,Inputs!$B$22))*(1+IF(I$5=2030,Inputs!$B$21,0)) -> 731.46818 | J7: =I7*(1+IF(J$5<=2029,Inputs!$B$20,Inputs!$B$22))*(1+IF(J$5=2030,Inputs!$B$21,0)) -> 768.04159 | ... L7: =K7*(1+IF(L$5<=2029,Inputs!$B$20,Inputs!$B$22))*(1+IF(L$5=2030,Inputs!$B$21,0)) -> 846.76586
A8: Local revenue | B8: =Inputs!$B$17 -> 191 | C8: =B8*(1+Inputs!$B$23)*(1+IF(C$5=Inputs!$B$25,Inputs!$B$24,0)) -> 196.73 | D8: =C8*(1+Inputs!$B$23)*(1+IF(D$5=Inputs!$B$25,Inputs!$B$24,0)) -> 202.6319 | E8: =D8*(1+Inputs!$B$23)*(1+IF(E$5=Inputs!$B$25,Inputs!$B$24,0)) -> 250.45303 | F8: =E8*(1+Inputs!$B$23)*(1+IF(F$5=Inputs!$B$25,Inputs!$B$24,0)) -> 257.96662 | G8: =F8*(1+Inputs!$B$23)*(1+IF(G$5=Inputs!$B$25,Inputs!$B$24,0)) -> 265.70562 | H8: =G8*(1+Inputs!$B$23)*(1+IF(H$5=Inputs!$B$25,Inputs!$B$24,0)) -> 273.67679 | I8: =H8*(1+Inputs!$B$23)*(1+IF(I$5=Inputs!$B$25,Inputs!$B$24,0)) -> 281.88709 | J8: =I8*(1+Inputs!$B$23)*(1+IF(J$5=Inputs!$B$25,Inputs!$B$24,0)) -> 290.3437 | ... L8: =K8*(1+Inputs!$B$23)*(1+IF(L$5=Inputs!$B$25,Inputs!$B$24,0)) -> 308.02563
A9: Total revenue | B9: =B7+B8 -> 646 | C9: =C7+C8 -> 679.03 | D9: =D7+D8 -> 713.8699 | E9: =E7+E8 -> 792.36531 | F9: =F7+F8 -> 832.39364 | G9: =G7+G8 -> 929.16882 | H9: =H7+H8 -> 970.31315 | I9: =I7+I8 -> 1013.3553 | ... L9: =L7+L8 -> 1154.7915
A10: growth | C10: =C9/B9-1 -> 0.051130031 | D10: =D9/C9-1 -> 0.051308337 | E10: =E9/D9-1 -> 0.10995758 | F10: =F9/E9-1 -> 0.050517517 | G10: =G9/F9-1 -> 0.11626132 | H10: =H9/G9-1 -> 0.044280789 | I10: =I9/H9-1 -> 0.044359001 | J10: =J9/I9-1 -> 0.044436559 | ... L10: =L9/K9-1 -> 0.044589694
A12: Player expenses | B12: =-Inputs!$B$10 -> -366 | C12: =B12*(1+Inputs!$B$26) -> -387.96 | D12: =C12*(1+Inputs!$B$26) -> -411.2376 | E12: =D12*(1+Inputs!$B$26) -> -435.91186 | F12: =E12*(1+Inputs!$B$26) -> -462.06657 | G12: =F12*(1+Inputs!$B$26) -> -489.79056 | H12: =G12*(1+Inputs!$B$26) -> -519.178 | I12: =H12*(1+Inputs!$B$26) -> -550.32867 | J12: =I12*(1+Inputs!$B$26) -> -583.3484 | ... L12: =K12*(1+Inputs!$B$26) -> -655.45026
A13: Other operating expenses | B13: =-Inputs!$B$18 -> -192 | C13: =B13*(1+Inputs!$B$27) -> -197.76 | D13: =C13*(1+Inputs!$B$27) -> -203.6928 | E13: =D13*(1+Inputs!$B$27) -> -209.80358 | F13: =E13*(1+Inputs!$B$27) -> -216.09769 | G13: =F13*(1+Inputs!$B$27) -> -222.58062 | H13: =G13*(1+Inputs!$B$27) -> -229.25804 | I13: =H13*(1+Inputs!$B$27) -> -236.13578 | J13: =I13*(1+Inputs!$B$27) -> -243.21986 | ... L13: =K13*(1+Inputs!$B$27) -> -258.03194
A14: EBITDA | B14: =B9+B12+B13 -> 88 | C14: =C9+C12+C13 -> 93.31 | D14: =D9+D12+D13 -> 98.9395 | E14: =E9+E12+E13 -> 146.64987 | F14: =F9+F12+F13 -> 154.22938 | G14: =G9+G12+G13 -> 216.79764 | H14: =H9+H12+H13 -> 221.87711 | I14: =I9+I12+I13 -> 226.89082 | ... L14: =L9+L12+L13 -> 241.30929
A15: margin | B15: =B14/B9 -> 0.13622291 | C15: =C14/C9 -> 0.13741661 | D15: =D14/D9 -> 0.13859598 | E15: =E14/E9 -> 0.18507861 | F15: =F14/F9 -> 0.18528419 | G15: =G14/G9 -> 0.23332427 | H15: =H14/H9 -> 0.22866547 | I15: =I14/I9 -> 0.22390056 | ... L15: =L14/L9 -> 0.20896351
A17: Taxes | C17: =-MAX(0,C14)*Inputs!$B$29 -> -23.3275 | D17: =-MAX(0,D14)*Inputs!$B$29 -> -24.734875 | E17: =-MAX(0,E14)*Inputs!$B$29 -> -36.662467 | F17: =-MAX(0,F14)*Inputs!$B$29 -> -38.557344 | G17: =-MAX(0,G14)*Inputs!$B$29 -> -54.19941 | H17: =-MAX(0,H14)*Inputs!$B$29 -> -55.469279 | I17: =-MAX(0,I14)*Inputs!$B$29 -> -56.722704 | J17: =-MAX(0,J14)*Inputs!$B$29 -> -57.954261 | ... L17: =-MAX(0,L14)*Inputs!$B$29 -> -60.327322
A18: Maintenance capex | C18: =-Inputs!$B$30 -> -10 | D18: =-Inputs!$B$30 -> -10 | E18: =-Inputs!$B$30 -> -10 | F18: =-Inputs!$B$30 -> -10 | G18: =-Inputs!$B$30 -> -10 | H18: =-Inputs!$B$30 -> -10 | I18: =-Inputs!$B$30 -> -10 | J18: =-Inputs!$B$30 -> -10 | ... L18: =-Inputs!$B$30 -> -10
A19: Stadium contributions (TSE) | C19: =-IF(C$5<=2029,Inputs!$B$31,Inputs!$B$32) -> -37.5 | D19: =-IF(D$5<=2029,Inputs!$B$31,Inputs!$B$32) -> -37.5 | E19: =-IF(E$5<=2029,Inputs!$B$31,Inputs!$B$32) -> -37.5 | F19: =-IF(F$5<=2029,Inputs!$B$31,Inputs!$B$32) -> -37.5 | G19: =-IF(G$5<=2029,Inputs!$B$31,Inputs!$B$32) -> -38 | H19: =-IF(H$5<=2029,Inputs!$B$31,Inputs!$B$32) -> -38 | I19: =-IF(I$5<=2029,Inputs!$B$31,Inputs!$B$32) -> -38 | J19: =-IF(J$5<=2029,Inputs!$B$31,Inputs!$B$32) -> -38 | ... L19: =-IF(L$5<=2029,Inputs!$B$31,Inputs!$B$32) -> -38
A20: Unlevered free cash flow | C20: =C14+C17+C18+C19 -> 22.4825 | D20: =D14+D17+D18+D19 -> 26.704625 | E20: =E14+E17+E18+E19 -> 62.487401 | F20: =F14+F17+F18+F19 -> 68.172033 | G20: =G14+G17+G18+G19 -> 114.59823 | H20: =H14+H17+H18+H19 -> 118.40784 | I20: =I14+I17+I18+I19 -> 122.16811 | J20: =J14+J17+J18+J19 -> 125.86278 | ... L20: =L14+L17+L18+L19 -> 132.98197
A22: Discount period (years) | C22: 1 | D22: 2 | E22: 3 | F22: 4 | G22: 5 | H22: 6 | I22: 7 | J22: 8 | K22: 9 | L22: 10
A23: Discount factor | C23: =1/(1+Inputs!$B$33)^C22 -> 0.92592593 | D23: =1/(1+Inputs!$B$33)^D22 -> 0.85733882 | E23: =1/(1+Inputs!$B$33)^E22 -> 0.79383224 | F23: =1/(1+Inputs!$B$33)^F22 -> 0.73502985 | G23: =1/(1+Inputs!$B$33)^G22 -> 0.6805832 | H23: =1/(1+Inputs!$B$33)^H22 -> 0.63016963 | I23: =1/(1+Inputs!$B$33)^I22 -> 0.5834904 | J23: =1/(1+Inputs!$B$33)^J22 -> 0.54026888 | ... L23: =1/(1+Inputs!$B$33)^L22 -> 0.46319349
A24: PV of FCF | C24: =C20*C23 -> 20.81713 | D24: =D20*D23 -> 22.894912 | E24: =E20*E23 -> 49.604514 | F24: =F20*F23 -> 50.108479 | G24: =G20*G23 -> 77.993629 | H24: =H20*H23 -> 74.617022 | I24: =I20*I23 -> 71.28392 | J24: =J20*J23 -> 67.999745 | ... L24: =L20*L23 -> 61.596381
A27: Valuation
A28: Sum of PV of FCF, 2026–2035 | B28: =SUM(C24:L24) -> 561.68494
A30: Method 1: Exit multiple (EV / 2035 revenue)
A31: Terminal value | B31: =L9*Inputs!$B$34 -> 13857.498
A32: PV of terminal value | B32: =B31*L23 -> 6418.7028
A33: Enterprise value | B33: =B28+B32 -> 6980.3877
A34: Implied EV / 2025 revenue | B34: =B33/B9 -> 10.805554
A36: Method 2: Perpetuity growth (Gordon)
A37: Terminal value | B37: =L20*(1+Inputs!$B$35)/(Inputs!$B$33-Inputs!$B$35) -> 3457.5311
A38: PV of terminal value | B38: =B37*L23 -> 1601.5059
A39: Enterprise value | B39: =B28+B38 -> 2163.1908
A40: Implied EV / 2025 revenue | B40: =B39/B9 -> 3.3485926
A42: Market value (Forbes) | B42: =Inputs!$B$6 -> 8100
A43: Scarcity premium: market value ÷ cash-flow value (Gordon) | B43: =B42/B39 -> 3.7444685
A44: Share of market value explained by cash flows | B44: =B39/B42 -> 0.2670606
A47: Sensitivity — Enterprise value ($mm), exit-multiple method
A48: Discount rate ↓ / Exit multiple → | B48: 10 | C48: 11 | D48: 12 | E48: 13 | F48: 14
A49: 0.07 | B49: =SUMPRODUCT($C$20:$L$20,1/(1+$A49)^$C$22:$L$22)+B$48*$L$9/(1+$A49)^$L$22 -> 6465.6944 | C49: =SUMPRODUCT($C$20:$L$20,1/(1+$A49)^$C$22:$L$22)+C$48*$L$9/(1+$A49)^$L$22 -> 7052.7319 | D49: =SUMPRODUCT($C$20:$L$20,1/(1+$A49)^$C$22:$L$22)+D$48*$L$9/(1+$A49)^$L$22 -> 7639.7693 | E49: =SUMPRODUCT($C$20:$L$20,1/(1+$A49)^$C$22:$L$22)+E$48*$L$9/(1+$A49)^$L$22 -> 8226.8067 | F49: =SUMPRODUCT($C$20:$L$20,1/(1+$A49)^$C$22:$L$22)+F$48*$L$9/(1+$A49)^$L$22 -> 8813.8442
A50: 0.08 | B50: =SUMPRODUCT($C$20:$L$20,1/(1+$A50)^$C$22:$L$22)+B$48*$L$9/(1+$A50)^$L$22 -> 5910.6039 | C50: =SUMPRODUCT($C$20:$L$20,1/(1+$A50)^$C$22:$L$22)+C$48*$L$9/(1+$A50)^$L$22 -> 6445.4958 | D50: =SUMPRODUCT($C$20:$L$20,1/(1+$A50)^$C$22:$L$22)+D$48*$L$9/(1+$A50)^$L$22 -> 6980.3877 | E50: =SUMPRODUCT($C$20:$L$20,1/(1+$A50)^$C$22:$L$22)+E$48*$L$9/(1+$A50)^$L$22 -> 7515.2796 | F50: =SUMPRODUCT($C$20:$L$20,1/(1+$A50)^$C$22:$L$22)+F$48*$L$9/(1+$A50)^$L$22 -> 8050.1715
A51: 0.09 | B51: =SUMPRODUCT($C$20:$L$20,1/(1+$A51)^$C$22:$L$22)+B$48*$L$9/(1+$A51)^$L$22 -> 5408.48 | C51: =SUMPRODUCT($C$20:$L$20,1/(1+$A51)^$C$22:$L$22)+C$48*$L$9/(1+$A51)^$L$22 -> 5896.2764 | D51: =SUMPRODUCT($C$20:$L$20,1/(1+$A51)^$C$22:$L$22)+D$48*$L$9/(1+$A51)^$L$22 -> 6384.0728 | E51: =SUMPRODUCT($C$20:$L$20,1/(1+$A51)^$C$22:$L$22)+E$48*$L$9/(1+$A51)^$L$22 -> 6871.8692 | F51: =SUMPRODUCT($C$20:$L$20,1/(1+$A51)^$C$22:$L$22)+F$48*$L$9/(1+$A51)^$L$22 -> 7359.6656
A52: 0.1 | B52: =SUMPRODUCT($C$20:$L$20,1/(1+$A52)^$C$22:$L$22)+B$48*$L$9/(1+$A52)^$L$22 -> 4953.8218 | C52: =SUMPRODUCT($C$20:$L$20,1/(1+$A52)^$C$22:$L$22)+C$48*$L$9/(1+$A52)^$L$22 -> 5399.0439 | D52: =SUMPRODUCT($C$20:$L$20,1/(1+$A52)^$C$22:$L$22)+D$48*$L$9/(1+$A52)^$L$22 -> 5844.266 | E52: =SUMPRODUCT($C$20:$L$20,1/(1+$A52)^$C$22:$L$22)+E$48*$L$9/(1+$A52)^$L$22 -> 6289.4881 | F52: =SUMPRODUCT($C$20:$L$20,1/(1+$A52)^$C$22:$L$22)+F$48*$L$9/(1+$A52)^$L$22 -> 6734.7102
...

Sheet PE Stake
A1: Would a Private-Equity Firm Earn Its Return Buying 10% of the Panthers?
A2: NFL rules: PE firms may own 3–10% of a team, must hold ≥6 years, and cannot take control. Returns come almost entirely from appreciation, not distributions.
B4: Bear | C4: Base | D4: Bull | E4: Notes
A5: Headline enterprise value today ($mm) | B5: =Inputs!$B$6 -> 8100 | C5: =Inputs!$B$6 -> 8100 | D5: =Inputs!$B$6 -> 8100
A6: Less: debt | B6: =-B5*Inputs!$B$11 -> -162 | C6: =-C5*Inputs!$B$11 -> -162 | D6: =-D5*Inputs!$B$11 -> -162
A7: Equity value, 100% | B7: =B5+B6 -> 7938 | C7: =C5+C6 -> 7938 | D7: =D5+D6 -> 7938
A8: LP discount | B8: =Inputs!$B$38 -> 0.2 | C8: =Inputs!$B$38 -> 0.2 | D8: =Inputs!$B$38 -> 0.2
A9: Stake purchased | B9: =Inputs!$B$37 -> 0.1 | C9: =Inputs!$B$37 -> 0.1 | D9: =Inputs!$B$37 -> 0.1
A10: Entry price for the stake ($mm) | B10: =B7*(1-B8)*B9 -> 635.04 | C10: =C7*(1-C8)*C9 -> 635.04 | D10: =D7*(1-D8)*D9 -> 635.04
A12: Annual appreciation of team value | B12: =Inputs!$B$41 -> 0.05 | C12: =Inputs!$B$40 -> 0.1 | D12: =Inputs!$B$42 -> 0.15
A13: Hold period (years) | B13: =Inputs!$B$39 -> 6 | C13: =Inputs!$B$39 -> 6 | D13: =Inputs!$B$39 -> 6
A14: Equity value at exit, 100% ($mm) | B14: =B7*(1+B12)^B13 -> 10637.679 | C14: =C7*(1+C12)^C13 -> 14062.651 | D14: =D7*(1+D12)^D13 -> 18361.076
A15: Discount at exit | B15: =Inputs!$B$43 -> 0.1 | C15: =Inputs!$B$43 -> 0.1 | D15: =Inputs!$B$43 -> 0.1
A16: Exit proceeds for the stake ($mm) | B16: =B14*(1-B15)*B9 -> 957.39113 | C16: =C14*(1-C15)*C9 -> 1265.6386 | D16: =D14*(1-D15)*D9 -> 1652.4969
A17: Cumulative distributions during hold ($mm) | B17: =SUM(DCF!$C$20:$H$20)*B9*0.5 -> 20.642631 | C17: =SUM(DCF!$C$20:$H$20)*C9*0.5 -> 20.642631 | D17: =SUM(DCF!$C$20:$H$20)*D9*0.5 -> 20.642631
A19: Multiple of invested capital (MOIC) | B19: =(B16+B17)/B10 -> 1.5401136 | C19: =(C16+C17)/C10 -> 2.0255122 | D19: =(D16+D17)/D10 -> 2.6346994
A20: IRR (approx., exit-weighted) | B20: =((B16+B17)/B10)^(1/B13)-1 -> 0.074629588 | C20: =((C16+C17)/C10)^(1/C13)-1 -> 0.12483583 | D20: =((D16+D17)/D10)^(1/D13)-1 -> 0.17522723
A21: Target IRR | B21: =Inputs!$B$44 -> 0.15 | C21: =Inputs!$B$44 -> 0.15 | D21: =Inputs!$B$44 -> 0.15
A22: Clears the hurdle? | B22: =IF(B20>=B21,"YES","NO") -> NO | C22: =IF(C20>=C21,"YES","NO") -> NO | D22: =IF(D20>=D21,"YES","NO") -> YES
A24: Break-even appreciation rate to hit target IRR | C24: =((1+C21)^C13*C10/((1-C15)*C9*C7))^(1/C13)-1 -> 0.12764506
A26: Verdict framework: the deal works only if NFL values keep compounding near 10%+ a year. The 20%→10% discount unwind adds roughly 2 points of IRR; cash yield adds under 1 point. So this is an appreciation bet on league media rights (2029 opt-out, 2033 renewal) and continued scarcity — not an operating investment.

Sheet Sources
A1: Sources
A3: Forbes — Carolina Panthers team page (value, revenue, operating income history) | B3: https://www.forbes.com/teams/carolina-panthers/
A4: Forbes — The NFL's Most Valuable Teams 2026 (Sept 9, 2026) | B4: https://www.forbes.com/sites/justinteitelbaum/2026/09/09/the-nfls-most-valuable-teams-2026/
A5: Sportico — NFL 2025 national revenue per team | B5: https://www.sportico.com/leagues/football/2026/nfl-2025-national-revenue-per-team-1234939659/
A6: Sportico — One year in, private equity boosts NFL values (PE rules, Bills/Dolphins/Chargers deals) | B6: https://www.sportico.com/business/finance/2025/nfl-private-equity-growth-sales-future-1234868441/
A7: CNBC — NFL approves Giants minority stake to Julia Koch at $10.3B | B7: https://www.cnbc.com/2025/10/22/nfl-sale-minority-stake-giants-koch.html
A8: CNBC — Official NFL Team Valuations 2025 | B8: https://www.cnbc.com/2025/09/04/cnbcs-official-nfl-team-valuations-2025.html
A9: WFAE — Charlotte City Council approves $650M for Bank of America Stadium renovations (June 24, 2024) | B9: https://www.wfae.org/politics/2024-06-24/in-7-3-vote-charlotte-city-council-approves-650m-for-bank-of-america-stadium-renovations
A10: Yahoo Sports / Charlotte Business Journal — Panthers more than double in value since 2018 | B10: https://sports.yahoo.com/articles/carolina-panthers-more-double-value-120232146.html
A11: Green Bay Packers annual financial report (public; use for exact national revenue) | B11: https://www.packers.com/community/shareholders
A12: SEC / company filings are not available — NFL teams are private. All team-level P&L figures are Forbes estimates.
